Workbook
Name SegmentaçãodeDados_DIA: #N/A
Name SegmentaçãodeDados_N1: #N/A

Sheet Resumo
L1: =SUM(L3:L6) -> 2090
I2: ="Volume Passageiros Vai e Vem: "&L1 -> Volume Passageiros Vai e Vem: 2090 | L2: Volume | M2: %
I3: Agend_NOK | J3: Não embarcou no horário ou local agendado | L3: =IFERROR(HLOOKUP(I3,$C$6:$G$7,2,0),0) -> 399 | M3: =L3/L1 -> 0.19090909
I4: Agend_OK | J4: Embarcou no horário e local agendado | L4: =IFERROR(HLOOKUP(I4,$C$6:$G$7,2,0),0) -> 270 | M4: =L4/L1 -> 0.1291866
I5: Encaixe | J5: Embarcou sem agendamento prévio | L5: =IFERROR(HLOOKUP(I5,$C$6:$G$7,2,0),0) -> 364 | M5: =L5/L1 -> 0.17416268
C6: =C9 -> Agend_NOK | D6: =D9 -> Agend_OK | E6: =E9 -> Encaixe | F6: =F9 -> Não Utilizou | G6: =G9 -> Total Geral | I6: Não Utilizou | J6: Agendou Vai e Vem, mas, não embarcou | L6: =IFERROR(HLOOKUP(I6,$C$6:$G$7,2,0),0) -> 1057 | M6: =L6/L1 -> 0.50574163
C7: =SUM(C10:C147) -> 399 | D7: =SUM(D10:D147) -> 270 | E7: =SUM(E10:E147) -> 364 | F7: =SUM(F10:F147) -> 1057 | G7: =SUM(G10:G147) -> 2090
B8: Contagem de NOME | C8: Rótulos de Coluna
B9: Rótulos de Linha | C9: Agend_NOK | D9: Agend_OK | E9: Encaixe | F9: Não Utilizou | G9: Total Geral
B10: Top Service | C10: 14 | D10: 63 | E10: 2 | F10: 165 | G10: 244
B11: IMAGEM EG | C11: 66 | D11: 12 | E11: 3 | F11: 93 | G11: 174
B12: SUPERVISAO EDITORIA RJ | C12: 9 | D12: 3 | E12: 14 | F12: 84 | G12: 110
B13: SUPERVISAO IMAGEM RJ | C13: 32 | D13: 6 | E13: 26 | F13: 59 | G13: 123
B14: MG2 | C14: 55 | D14: 17 | E14: 11 | F14: 47 | G14: 130
B15: IMAGEM ION | C15: 12 | D15: 6 | E15: 1 | F15: 42 | G15: 61
B16: CAPTACAO EVENTOS ION | C16: 7 | D16: 5 | E16: 11 | F16: 40 | G16: 63
B17: IMAGEM JB | C17: 16 | D17: 4 | F17: 28 | G17: 48
B18: SUPERVISAO EDITORIA RJ 03 04 | C18: 3 | D18: 6 | E18: 4 | F18: 24 | G18: 37
B19: PROJETOS DE PRODUCAO E DISTRIBUICAO DE CONTEUDO | C19: 4 | E19: 1 | F19: 20 | G19: 25
B20: TECNOLOGIA PARA SHOWS E EVENTOS | C20: 10 | D20: 4 | E20: 4 | F20: 18 | G20: 36
B21: LET | C21: 5 | D21: 2 | F21: 17 | G21: 24
B22: Randstad | F22: 16 | G22: 16
B23: EDITORIA RJ 03 | F23: 16 | G23: 16
B24: RTpress Imagens | F24: 16 | G24: 16
B25: I9tv | F25: 16 | G25: 16
B26: Teleprompter Carioca Ltda. | F26: 16 | G26: 16
B27: REDACAO SERIES E REALITIES | C27: 1 | F27: 15 | G27: 16
B28: SUPERVISAO EDITORIA RJ 01 01 | F28: 14 | G28: 14
B29: Gilberto Merguizo Management Studio Eireli (CAPA MGT ) | C29: 2 | F29: 14 | G29: 16
B30: CIS | C30: 1 | F30: 14 | G30: 15
B31: REDES SOCIAIS GSHOW E RECEITAS | C31: 7 | D31: 4 | E31: 1 | F31: 13 | G31: 25
B32: DRAMATURGIA DIARIA | C32: 22 | D32: 4 | F32: 13 | G32: 39
B33: COT E EXTERNA ION | F33: 12 | G33: 12
B34: CULTURA POP 2 | C34: 6 | D34: 4 | F34: 12 | G34: 22
B35: Gilberto Merguizo Management Studio Eireli ( CAPA MGT) | C35: 3 | D35: 2 | F35: 11 | G35: 16
B36: SOL DE RELACIONAMENTO - CONTEUDO - ENTRETENIMENTO | C36: 4 | D36: 2 | F36: 10 | G36: 16
B37: SUPORTE PRODUCAO PRODUTOS E PLATAFORMAS RJ | C37: 6 | D37: 3 | E37: 9 | F37: 10 | G37: 28
B38: TRANSPORTES RJ | C38: 5 | D38: 9 | E38: 43 | F38: 10 | G38: 67
B39: SUPERVISAO EDITORIA G1 01 03 - 01 | C39: 3 | D39: 2 | F39: 9 | G39: 14
B40: EDITORIA RJ | C40: 5 | D40: 7 | F40: 8 | G40: 20
...

Sheet Agendamento
A1: Chave Agend | B1: Chave data | C1: Status Agend | D1: NOME COMPLETO | E1: EMPRESA | F1: MATRÍCULA | G1: CPF (somente números) | H1: DDD + TELEFONE | I1: DIRETORIA | J1: Departamento | K1: Gestor Imediato | L1: Cargo | M1: Agendamento Original | N1: Ag. Orig. | O1: Movimentação | P1: Data | Q1: Hr
A2: =IF(LEN(F2)>1,F2,G2)&O2&P2&Q2 -> 32636EG x Sambodromo4606818h | B2: =IF(LEN(F2)>1,F2,G2)&O2&P2 -> 32636EG x Sambodromo46068 | C2: =IF((IFERROR(IFERROR(VLOOKUP(A2,Controle_Utiliz!A:A,1,0),VLOOKUP(B2,Controle_Utiliz!B:B,1,0)),"Não Utilizou"))="Não Utilizou","Não Utilizou","Agendado") -> Agendado | D2: Adilson Pereira Coutinho | E2: Globo | F2: 32636 | H2: 21964555352 | I2: ESTRATÉGIA E TECNOLOGIA | J2: IMAGEM JB | K2: JEAN CARLO GOULART ALVES | L2: OPER CAMERA II | M2: EG x Sambódromo | Vai [1º Dia, Dom, 15-Fev (Grupo Especial)] | N2: 18:00 | O2: EG x Sambodromo | P2: 46068 | Q2: =LEFT(N2,2)&"h" -> 18h
A3: =IF(LEN(F3)>1,F3,G3)&O3&P3&Q3 -> 32636EG x Sambodromo4606918h | B3: =IF(LEN(F3)>1,F3,G3)&O3&P3 -> 32636EG x Sambodromo46069 | C3: =IF((IFERROR(IFERROR(VLOOKUP(A3,Controle_Utiliz!A:A,1,0),VLOOKUP(B3,Controle_Utiliz!B:B,1,0)),"Não Utilizou"))="Não Utilizou","Não Utilizou","Agendado") -> Agendado | D3: Adilson Pereira Coutinho | E3: Globo | F3: 32636 | H3: 21964555352 | I3: ESTRATÉGIA E TECNOLOGIA | J3: IMAGEM JB | K3: JEAN CARLO GOULART ALVES | L3: OPER CAMERA II | M3: EG x Sambódromo | Vai [2º Dia, Seg, 16-Fev (Grupo Especial)] | N3: 18:00 | O3: EG x Sambodromo | P3: 46069 | Q3: =LEFT(N3,2)&"h" -> 18h
A4: =IF(LEN(F4)>1,F4,G4)&O4&P4&Q4 -> 32636EG x Sambodromo4607018h | B4: =IF(LEN(F4)>1,F4,G4)&O4&P4 -> 32636EG x Sambodromo46070 | C4: =IF((IFERROR(IFERROR(VLOOKUP(A4,Controle_Utiliz!A:A,1,0),VLOOKUP(B4,Controle_Utiliz!B:B,1,0)),"Não Utilizou"))="Não Utilizou","Não Utilizou","Agendado") -> Agendado | D4: Adilson Pereira Coutinho | E4: Globo | F4: 32636 | H4: 21964555352 | I4: ESTRATÉGIA E TECNOLOGIA | J4: IMAGEM JB | K4: JEAN CARLO GOULART ALVES | L4: OPER CAMERA II | M4: EG x Sambódromo | Vai [3º Dia, Ter, 17-Fev (Grupo Especial)] | N4: 18:00 | O4: EG x Sambodromo | P4: 46070 | Q4: =LEFT(N4,2)&"h" -> 18h
A5: =IF(LEN(F5)>1,F5,G5)&O5&P5&Q5 -> 32636EG x Sambodromo4607418h | B5: =IF(LEN(F5)>1,F5,G5)&O5&P5 -> 32636EG x Sambodromo46074 | C5: =IF((IFERROR(IFERROR(VLOOKUP(A5,Controle_Utiliz!A:A,1,0),VLOOKUP(B5,Controle_Utiliz!B:B,1,0)),"Não Utilizou"))="Não Utilizou","Não Utilizou","Agendado") -> Agendado | D5: Adilson Pereira Coutinho | E5: Globo | F5: 32636 | H5: 21964555352 | I5: ESTRATÉGIA E TECNOLOGIA | J5: IMAGEM JB | K5: JEAN CARLO GOULART ALVES | L5: OPER CAMERA II | M5: EG x Sambódromo | Vai [CAMPEÃES, Sáb, 21-Fev (Desfile das Campeãs).] | N5: 18:00 | O5: EG x Sambodromo | P5: 46074 | Q5: =LEFT(N5,2)&"h" -> 18h
A6: =IF(LEN(F6)>1,F6,G6)&O6&P6&Q6 -> 32636Sambodromo x EG4606805h | B6: =IF(LEN(F6)>1,F6,G6)&O6&P6 -> 32636Sambodromo x EG46068 | C6: =IF((IFERROR(IFERROR(VLOOKUP(A6,Controle_Utiliz!A:A,1,0),VLOOKUP(B6,Controle_Utiliz!B:B,1,0)),"Não Utilizou"))="Não Utilizou","Não Utilizou","Agendado") -> Não Utilizou | D6: Adilson Pereira Coutinho | E6: Globo | F6: 32636 | H6: 21964555352 | I6: ESTRATÉGIA E TECNOLOGIA | J6: IMAGEM JB | K6: JEAN CARLO GOULART ALVES | L6: OPER CAMERA II | M6: Sambódromo x EG | Vem [1º Dia, Dom, 15-Fev (Grupo Especial)] | N6: 05:00 | O6: Sambodromo x EG | P6: 46068 | Q6: =LEFT(N6,2)&"h" -> 05h
A7: =IF(LEN(F7)>1,F7,G7)&O7&P7&Q7 -> 32636Sambodromo x EG4606905h | B7: =IF(LEN(F7)>1,F7,G7)&O7&P7 -> 32636Sambodromo x EG46069 | C7: =IF((IFERROR(IFERROR(VLOOKUP(A7,Controle_Utiliz!A:A,1,0),VLOOKUP(B7,Controle_Utiliz!B:B,1,0)),"Não Utilizou"))="Não Utilizou","Não Utilizou","Agendado") -> Agendado | D7: Adilson Pereira Coutinho | E7: Globo | F7: 32636 | H7: 21964555352 | I7: ESTRATÉGIA E TECNOLOGIA | J7: IMAGEM JB | K7: JEAN CARLO GOULART ALVES | L7: OPER CAMERA II | M7: Sambódromo x EG | Vem [2º Dia, Seg, 16-Fev (Grupo Especial)] | N7: 05:00 | O7: Sambodromo x EG | P7: 46069 | Q7: =LEFT(N7,2)&"h" -> 05h
A8: =IF(LEN(F8)>1,F8,G8)&O8&P8&Q8 -> 32636Sambodromo x EG4607005h | B8: =IF(LEN(F8)>1,F8,G8)&O8&P8 -> 32636Sambodromo x EG46070 | C8: =IF((IFERROR(IFERROR(VLOOKUP(A8,Controle_Utiliz!A:A,1,0),VLOOKUP(B8,Controle_Utiliz!B:B,1,0)),"Não Utilizou"))="Não Utilizou","Não Utilizou","Agendado") -> Agendado | D8: Adilson Pereira Coutinho | E8: Globo | F8: 32636 | H8: 21964555352 | I8: ESTRATÉGIA E TECNOLOGIA | J8: IMAGEM JB | K8: JEAN CARLO GOULART ALVES | L8: OPER CAMERA II | M8: Sambódromo x EG | Vem [3º Dia, Ter, 17-Fev (Grupo Especial)] | N8: 05:00 | O8: Sambodromo x EG | P8: 46070 | Q8: =LEFT(N8,2)&"h" -> 05h
A9: =IF(LEN(F9)>1,F9,G9)&O9&P9&Q9 -> 32636Sambodromo x EG4607405h | B9: =IF(LEN(F9)>1,F9,G9)&O9&P9 -> 32636Sambodromo x EG46074 | C9: =IF((IFERROR(IFERROR(VLOOKUP(A9,Controle_Utiliz!A:A,1,0),VLOOKUP(B9,Controle_Utiliz!B:B,1,0)),"Não Utilizou"))="Não Utilizou","Não Utilizou","Agendado") -> Agendado | D9: Adilson Pereira Coutinho | E9: Globo | F9: 32636 | H9: 21964555352 | I9: ESTRATÉGIA E TECNOLOGIA | J9: IMAGEM JB | K9: JEAN CARLO GOULART ALVES | L9: OPER CAMERA II | M9: Sambódromo x EG | Vem [CAMPEÃES, Sáb, 21-Fev (Desfile das Campeãs).] | N9: 05:00 | O9: Sambodromo x EG | P9: 46074 | Q9: =LEFT(N9,2)&"h" -> 05h
A10: =IF(LEN(F10)>1,F10,G10)&O10&P10&Q10 -> 32636JB x Sambodromo4606818h | B10: =IF(LEN(F10)>1,F10,G10)&O10&P10 -> 32636JB x Sambodromo46068 | C10: =IF((IFERROR(IFERROR(VLOOKUP(A10,Controle_Utiliz!A:A,1,0),VLOOKUP(B10,Controle_Utiliz!B:B,1,0)),"Não Utilizou"))="Não Utilizou","Não Utilizou","Agendado") -> Não Utilizou | D10: Adilson Pereira Coutinho | E10: Globo | F10: 32636 | H10: 21964555352 | I10: ESTRATÉGIA E TECNOLOGIA | J10: IMAGEM JB | K10: JEAN CARLO GOULART ALVES | L10: OPER CAMERA II | M10: JB x Sambódromo | Vai [1º Dia, Dom, 15-Fev (Grupo Especial)] | N10: 18:00 | O10: JB x Sambodromo | P10: 46068 | Q10: =LEFT(N10,2)&"h" -> 18h
A11: =IF(LEN(F11)>1,F11,G11)&O11&P11&Q11 -> 32636JB x Sambodromo4606918h | B11: =IF(LEN(F11)>1,F11,G11)&O11&P11 -> 32636JB x Sambodromo46069 | C11: =IF((IFERROR(IFERROR(VLOOKUP(A11,Controle_Utiliz!A:A,1,0),VLOOKUP(B11,Controle_Utiliz!B:B,1,0)),"Não Utilizou"))="Não Utilizou","Não Utilizou","Agendado") -> Não Utilizou | D11: Adilson Pereira Coutinho | E11: Globo | F11: 32636 | H11: 21964555352 | I11: ESTRATÉGIA E TECNOLOGIA | J11: IMAGEM JB | K11: JEAN CARLO GOULART ALVES | L11: OPER CAMERA II | M11: JB x Sambódromo | Vai [2º Dia, Seg, 16-Fev (Grupo Especial)] | N11: 18:00 | O11: JB x Sambodromo | P11: 46069 | Q11: =LEFT(N11,2)&"h" -> 18h
A12: =IF(LEN(F12)>1,F12,G12)&O12&P12&Q12 -> 32636JB x Sambodromo4607018h | B12: =IF(LEN(F12)>1,F12,G12)&O12&P12 -> 32636JB x Sambodromo46070 | C12: =IF((IFERROR(IFERROR(VLOOKUP(A12,Controle_Utiliz!A:A,1,0),VLOOKUP(B12,Controle_Utiliz!B:B,1,0)),"Não Utilizou"))="Não Utilizou","Não Utilizou","Agendado") -> Não Utilizou | D12: Adilson Pereira Coutinho | E12: Globo | F12: 32636 | H12: 21964555352 | I12: ESTRATÉGIA E TECNOLOGIA | J12: IMAGEM JB | K12: JEAN CARLO GOULART ALVES | L12: OPER CAMERA II | M12: JB x Sambódromo | Vai [3º Dia, Ter, 17-Fev (Grupo Especial)] | N12: 18:00 | O12: JB x Sambodromo | P12: 46070 | Q12: =LEFT(N12,2)&"h" -> 18h
A13: =IF(LEN(F13)>1,F13,G13)&O13&P13&Q13 -> 32636JB x Sambodromo4607418h | B13: =IF(LEN(F13)>1,F13,G13)&O13&P13 -> 32636JB x Sambodromo46074 | C13: =IF((IFERROR(IFERROR(VLOOKUP(A13,Controle_Utiliz!A:A,1,0),VLOOKUP(B13,Controle_Utiliz!B:B,1,0)),"Não Utilizou"))="Não Utilizou","Não Utilizou","Agendado") -> Não Utilizou | D13: Adilson Pereira Coutinho | E13: Globo | F13: 32636 | H13: 21964555352 | I13: ESTRATÉGIA E TECNOLOGIA | J13: IMAGEM JB | K13: JEAN CARLO GOULART ALVES | L13: OPER CAMERA II | M13: JB x Sambódromo | Vai [CAMPEÃES, Sáb, 21-Fev (Desfile das Campeãs).] | N13: 18:00 | O13: JB x Sambodromo | P13: 46074 | Q13: =LEFT(N13,2)&"h" -> 18h
... A17: =IF(LEN(F17)>1,F17,G17)&O17&P17&Q17 -> 32636Sambodromo x JB4607405h | B17: =IF(LEN(F17)>1,F17,G17)&O17&P17 -> 32636Sambodromo x JB46074 | C17: =IF((IFERROR(IFERROR(VLOOKUP(A17,Controle_Utiliz!A:A,1,0),VLOOKUP(B17,Controle_Utiliz!B:B,1,0)),"Não Utilizou"))="Não Utilizou","Não Utilizou","Agendado") -> Não Utilizou | D17: Adilson Pereira Coutinho | E17: Globo | F17: 32636 | H17: 21964555352 | I17: ESTRATÉGIA E TECNOLOGIA | J17: IMAGEM JB | K17: JEAN CARLO GOULART ALVES | L17: OPER CAMERA II | M17: Sambódromo x JB | Vem [CAMPEÃES, Sáb, 21-Fev (Desfile das Campeãs).] | N17: 05:00 | O17: Sambodromo x JB | P17: 46074 | Q17: =LEFT(N17,2)&"h" -> 05h
A18: =IF(LEN(F18)>1,F18,G18)&O18&P18&Q18 -> 15974990722EG x Sambodromo4606817h | B18: =IF(LEN(F18)>1,F18,G18)&O18&P18 -> 15974990722EG x Sambodromo46068 | C18: =IF((IFERROR(IFERROR(VLOOKUP(A18,Controle_Utiliz!A:A,1,0),VLOOKUP(B18,Controle_Utiliz!B:B,1,0)),"Não Utilizou"))="Não Utilizou","Não Utilizou","Agendado") -> Não Utilizou | D18: Alana Chicharo Ferreira | E18: Gilberto Merguizo Management Studio Eireli ( CAPA MGT) | G18: 15974990722 | H18: 21990091564 | I18: TV GLOBO | J18: Gilberto Merguizo Management Studio Eireli ( CAPA MGT) | K18: Gilberto Merguizo Management Studio Eireli ( CAPA MGT) | L18: Gilberto Merguizo Management Studio Eireli ( CAPA MGT) | M18: EG x Sambódromo | Vai [1º Dia, Dom, 15-Fev (Grupo Especial)] | N18: 17:00 | O18: EG x Sambodromo | P18: 46068 | Q18: =LEFT(N18,2)&"h" -> 17h
A19: =IF(LEN(F19)>1,F19,G19)&O19&P19&Q19 -> 15974990722EG x Sambodromo4606917h | B19: =IF(LEN(F19)>1,F19,G19)&O19&P19 -> 15974990722EG x Sambodromo46069 | C19: =IF((IFERROR(IFERROR(VLOOKUP(A19,Controle_Utiliz!A:A,1,0),VLOOKUP(B19,Controle_Utiliz!B:B,1,0)),"Não Utilizou"))="Não Utilizou","Não Utilizou","Agendado") -> Não Utilizou | D19: Alana Chicharo Ferreira | E19: Gilberto Merguizo Management Studio Eireli ( CAPA MGT) | G19: 15974990722 | H19: 21990091564 | I19: TV GLOBO | J19: Gilberto Merguizo Management Studio Eireli ( CAPA MGT) | K19: Gilberto Merguizo Management Studio Eireli ( CAPA MGT) | L19: Gilberto Merguizo Management Studio Eireli ( CAPA MGT) | M19: EG x Sambódromo | Vai [2º Dia, Seg, 16-Fev (Grupo Especial)] | N19: 17:00 | O19: EG x Sambodromo | P19: 46069 | Q19: =LEFT(N19,2)&"h" -> 17h
A20: =IF(LEN(F20)>1,F20,G20)&O20&P20&Q20 -> 15974990722EG x Sambodromo4607017h | B20: =IF(LEN(F20)>1,F20,G20)&O20&P20 -> 15974990722EG x Sambodromo46070 | C20: =IF((IFERROR(IFERROR(VLOOKUP(A20,Controle_Utiliz!A:A,1,0),VLOOKUP(B20,Controle_Utiliz!B:B,1,0)),"Não Utilizou"))="Não Utilizou","Não Utilizou","Agendado") -> Não Utilizou | D20: Alana Chicharo Ferreira | E20: Gilberto Merguizo Management Studio Eireli ( CAPA MGT) | G20: 15974990722 | H20: 21990091564 | I20: TV GLOBO | J20: Gilberto Merguizo Management Studio Eireli ( CAPA MGT) | K20: Gilberto Merguizo Management Studio Eireli ( CAPA MGT) | L20: Gilberto Merguizo Management Studio Eireli ( CAPA MGT) | M20: EG x Sambódromo | Vai [3º Dia, Ter, 17-Fev (Grupo Especial)] | N20: 17:00 | O20: EG x Sambodromo | P20: 46070 | Q20: =LEFT(N20,2)&"h" -> 17h
A21: =IF(LEN(F21)>1,F21,G21)&O21&P21&Q21 -> 15974990722EG x Sambodromo4607417h | B21: =IF(LEN(F21)>1,F21,G21)&O21&P21 -> 15974990722EG x Sambodromo46074 | C21: =IF((IFERROR(IFERROR(VLOOKUP(A21,Controle_Utiliz!A:A,1,0),VLOOKUP(B21,Controle_Utiliz!B:B,1,0)),"Não Utilizou"))="Não Utilizou","Não Utilizou","Agendado") -> Não Utilizou | D21: Alana Chicharo Ferreira | E21: Gilberto Merguizo Management Studio Eireli ( CAPA MGT) | G21: 15974990722 | H21: 21990091564 | I21: TV GLOBO | J21: Gilberto Merguizo Management Studio Eireli ( CAPA MGT) | K21: Gilberto Merguizo Management Studio Eireli ( CAPA MGT) | L21: Gilberto Merguizo Management Studio Eireli ( CAPA MGT) | M21: EG x Sambódromo | Vai [CAMPEÃES, Sáb, 21-Fev (Desfile das Campeãs).] | N21: 17:00 | O21: EG x Sambodromo | P21: 46074 | Q21: =LEFT(N21,2)&"h" -> 17h
A22: =IF(LEN(F22)>1,F22,G22)&O22&P22&Q22 -> 15974990722Sambodromo x EG4606802h | B22: =IF(LEN(F22)>1,F22,G22)&O22&P22 -> 15974990722Sambodromo x EG46068 | C22: =IF((IFERROR(IFERROR(VLOOKUP(A22,Controle_Utiliz!A:A,1,0),VLOOKUP(B22,Controle_Utiliz!B:B,1,0)),"Não Utilizou"))="Não Utilizou","Não Utilizou","Agendado") -> Agendado | D22: Alana Chicharo Ferreira | E22: Gilberto Merguizo Management Studio Eireli ( CAPA MGT) | G22: 15974990722 | H22: 21990091564 | I22: TV GLOBO | J22: Gilberto Merguizo Management Studio Eireli ( CAPA MGT) | K22: Gilberto Merguizo Management Studio Eireli ( CAPA MGT) | L22: Gilberto Merguizo Management Studio Eireli ( CAPA MGT) | M22: Sambódromo x EG | Vem [1º Dia, Dom, 15-Fev (Grupo Especial)] | N22: 02:00 | O22: Sambodromo x EG | P22: 46068 | Q22: =LEFT(N22,2)&"h" -> 02h
A23: =IF(LEN(F23)>1,F23,G23)&O23&P23&Q23 -> 15974990722Sambodromo x EG4606902h | B23: =IF(LEN(F23)>1,F23,G23)&O23&P23 -> 15974990722Sambodromo x EG46069 | C23: =IF((IFERROR(IFERROR(VLOOKUP(A23,Controle_Utiliz!A:A,1,0),VLOOKUP(B23,Controle_Utiliz!B:B,1,0)),"Não Utilizou"))="Não Utilizou","Não Utilizou","Agendado") -> Não Utilizou | D23: Alana Chicharo Ferreira | E23: Gilberto Merguizo Management Studio Eireli ( CAPA MGT) | G23: 15974990722 | H23: 21990091564 | I23: TV GLOBO | J23: Gilberto Merguizo Management Studio Eireli ( CAPA MGT) | K23: Gilberto Merguizo Management Studio Eireli ( CAPA MGT) | L23: Gilberto Merguizo Management Studio Eireli ( CAPA MGT) | M23: Sambódromo x EG | Vem [2º Dia, Seg, 16-Fev (Grupo Especial)] | N23: 02:00 | O23: Sambodromo x EG | P23: 46069 | Q23: =LEFT(N23,2)&"h" -> 02h
A24: =IF(LEN(F24)>1,F24,G24)&O24&P24&Q24 -> 15974990722Sambodromo x EG4607002h | B24: =IF(LEN(F24)>1,F24,G24)&O24&P24 -> 15974990722Sambodromo x EG46070 | C24: =IF((IFERROR(IFERROR(VLOOKUP(A24,Controle_Utiliz!A:A,1,0),VLOOKUP(B24,Controle_Utiliz!B:B,1,0)),"Não Utilizou"))="Não Utilizou","Não Utilizou","Agendado") -> Não Utilizou | D24: Alana Chicharo Ferreira | E24: Gilberto Merguizo Management Studio Eireli ( CAPA MGT) | G24: 15974990722 | H24: 21990091564 | I24: TV GLOBO | J24: Gilberto Merguizo Management Studio Eireli ( CAPA MGT) | K24: Gilberto Merguizo Management Studio Eireli ( CAPA MGT) | L24: Gilberto Merguizo Management Studio Eireli ( CAPA MGT) | M24: Sambódromo x EG | Vem [3º Dia, Ter, 17-Fev (Grupo Especial)] | N24: 02:00 | O24: Sambodromo x EG | P24: 46070 | Q24: =LEFT(N24,2)&"h" -> 02h
A25: =IF(LEN(F25)>1,F25,G25)&O25&P25&Q25 -> 15974990722Sambodromo x EG4607402h | B25: =IF(LEN(F25)>1,F25,G25)&O25&P25 -> 15974990722Sambodromo x EG46074 | C25: =IF((IFERROR(IFERROR(VLOOKUP(A25,Controle_Utiliz!A:A,1,0),VLOOKUP(B25,Controle_Utiliz!B:B,1,0)),"Não Utilizou"))="Não Utilizou","Não Utilizou","Agendado") -> Não Utilizou | D25: Alana Chicharo Ferreira | E25: Gilberto Merguizo Management Studio Eireli ( CAPA MGT) | G25: 15974990722 | H25: 21990091564 | I25: TV GLOBO | J25: Gilberto Merguizo Management Studio Eireli ( CAPA MGT) | K25: Gilberto Merguizo Management Studio Eireli ( CAPA MGT) | L25: Gilberto Merguizo Management Studio Eireli ( CAPA MGT) | M25: Sambódromo x EG | Vem [CAMPEÃES, Sáb, 21-Fev (Desfile das Campeãs).] | N25: 02:00 | O25: Sambodromo x EG | P25: 46074 | Q25: =LEFT(N25,2)&"h" -> 02h
A26: =IF(LEN(F26)>1,F26,G26)&O26&P26&Q26 -> 03139095473EG x Sambodromo4606818h | B26: =IF(LEN(F26)>1,F26,G26)&O26&P26 -> 03139095473EG x Sambodromo46068 | C26: =IF((IFERROR(IFERROR(VLOOKUP(A26,Controle_Utiliz!A:A,1,0),VLOOKUP(B26,Controle_Utiliz!B:B,1,0)),"Não Utilizou"))="Não Utilizou","Não Utilizou","Agendado") -> Agendado | D26: ALBERTO CAVALCANTI LIRA DA SILVA | E26: Prestador - Top Service | G26: 03139095473 | H26: 21967041708 | I26: FJI - CSC OGA | J26: Prestador - Top Service | K26: Prestador - Top Service | L26: Prestador - Top Service | M26: EG x Sambódromo | Vai [1º Dia, Dom, 15-Fev (Grupo Especial)] | N26: 18:00 | O26: EG x Sambodromo | P26: 46068 | Q26: =LEFT(N26,2)&"h" -> 18h
A27: =IF(LEN(F27)>1,F27,G27)&O27&P27&Q27 -> 03139095473EG x Sambodromo4606918h | B27: =IF(LEN(F27)>1,F27,G27)&O27&P27 -> 03139095473EG x Sambodromo46069 | C27: =IF((IFERROR(IFERROR(VLOOKUP(A27,Controle_Utiliz!A:A,1,0),VLOOKUP(B27,Controle_Utiliz!B:B,1,0)),"Não Utilizou"))="Não Utilizou","Não Utilizou","Agendado") -> Agendado | D27: ALBERTO CAVALCANTI LIRA DA SILVA | E27: Prestador - Top Service | G27: 03139095473 | H27: 21967041708 | I27: FJI - CSC OGA | J27: Prestador - Top Service | K27: Prestador - Top Service | L27: Prestador - Top Service | M27: EG x Sambódromo | Vai [2º Dia, Seg, 16-Fev (Grupo Especial)] | N27: 18:00 | O27: EG x Sambodromo | P27: 46069 | Q27: =LEFT(N27,2)&"h" -> 18h
A28: =IF(LEN(F28)>1,F28,G28)&O28&P28&Q28 -> 03139095473EG x Sambodromo4607018h | B28: =IF(LEN(F28)>1,F28,G28)&O28&P28 -> 03139095473EG x Sambodromo46070 | C28: =IF((IFERROR(IFERROR(VLOOKUP(A28,Controle_Utiliz!A:A,1,0),VLOOKUP(B28,Controle_Utiliz!B:B,1,0)),"Não Utilizou"))="Não Utilizou","Não Utilizou","Agendado") -> Agendado | D28: ALBERTO CAVALCANTI LIRA DA SILVA | E28: Prestador - Top Service | G28: 03139095473 | H28: 21967041708 | I28: FJI - CSC OGA | J28: Prestador - Top Service | K28: Prestador - Top Service | L28: Prestador - Top Service | M28: EG x Sambódromo | Vai [3º Dia, Ter, 17-Fev (Grupo Especial)] | N28: 18:00 | O28: EG x Sambodromo | P28: 46070 | Q28: =LEFT(N28,2)&"h" -> 18h
A29: =IF(LEN(F29)>1,F29,G29)&O29&P29&Q29 -> 03139095473EG x Sambodromo4607418h | B29: =IF(LEN(F29)>1,F29,G29)&O29&P29 -> 03139095473EG x Sambodromo46074 | C29: =IF((IFERROR(IFERROR(VLOOKUP(A29,Controle_Utiliz!A:A,1,0),VLOOKUP(B29,Controle_Utiliz!B:B,1,0)),"Não Utilizou"))="Não Utilizou","Não Utilizou","Agendado") -> Não Utilizou | D29: ALBERTO CAVALCANTI LIRA DA SILVA | E29: Prestador - Top Service | G29: 03139095473 | H29: 21967041708 | I29: FJI - CSC OGA | J29: Prestador - Top Service | K29: Prestador - Top Service | L29: Prestador - Top Service | M29: EG x Sambódromo | Vai [CAMPEÃES, Sáb, 21-Fev (Desfile das Campeãs).] | N29: 18:00 | O29: EG x Sambodromo | P29: 46074 | Q29: =LEFT(N29,2)&"h" -> 18h
A30: =IF(LEN(F30)>1,F30,G30)&O30&P30&Q30 -> 03139095473Sambodromo x EG4606806h | B30: =IF(LEN(F30)>1,F30,G30)&O30&P30 -> 03139095473Sambodromo x EG46068 | C30: =IF((IFERROR(IFERROR(VLOOKUP(A30,Controle_Utiliz!A:A,1,0),VLOOKUP(B30,Controle_Utiliz!B:B,1,0)),"Não Utilizou"))="Não Utilizou","Não Utilizou","Agendado") -> Não Utilizou | D30: ALBERTO CAVALCANTI LIRA DA SILVA | E30: Prestador - Top Service | G30: 03139095473 | H30: 21967041708 | I30: FJI - CSC OGA | J30: Prestador - Top Service | K30: Prestador - Top Service | L30: Prestador - Top Service | M30: Sambódromo x EG | Vem [1º Dia, Dom, 15-Fev (Grupo Especial)] | N30: 06:00 | O30: Sambodromo x EG | P30: 46068 | Q30: =LEFT(N30,2)&"h" -> 06h
A31: =IF(LEN(F31)>1,F31,G31)&O31&P31&Q31 -> 03139095473Sambodromo x EG4606906h | B31: =IF(LEN(F31)>1,F31,G31)&O31&P31 -> 03139095473Sambodromo x EG46069 | C31: =IF((IFERROR(IFERROR(VLOOKUP(A31,Controle_Utiliz!A:A,1,0),VLOOKUP(B31,Controle_Utiliz!B:B,1,0)),"Não Utilizou"))="Não Utilizou","Não Utilizou","Agendado") -> Não Utilizou | D31: ALBERTO CAVALCANTI LIRA DA SILVA | E31: Prestador - Top Service | G31: 03139095473 | H31: 21967041708 | I31: FJI - CSC OGA | J31: Prestador - Top Service | K31: Prestador - Top Service | L31: Prestador - Top Service | M31: Sambódromo x EG | Vem [2º Dia, Seg, 16-Fev (Grupo Especial)] | N31: 06:00 | O31: Sambodromo x EG | P31: 46069 | Q31: =LEFT(N31,2)&"h" -> 06h
A32: =IF(LEN(F32)>1,F32,G32)&O32&P32&Q32 -> 03139095473Sambodromo x EG4607006h | B32: =IF(LEN(F32)>1,F32,G32)&O32&P32 -> 03139095473Sambodromo x EG46070 | C32: =IF((IFERROR(IFERROR(VLOOKUP(A32,Controle_Utiliz!A:A,1,0),VLOOKUP(B32,Controle_Utiliz!B:B,1,0)),"Não Utilizou"))="Não Utilizou","Não Utilizou","Agendado") -> Agendado | D32: ALBERTO CAVALCANTI LIRA DA SILVA | E32: Prestador - Top Service | G32: 03139095473 | H32: 21967041708 | I32: FJI - CSC OGA | J32: Prestador - Top Service | K32: Prestador - Top Service | L32: Prestador - Top Service | M32: Sambódromo x EG | Vem [3º Dia, Ter, 17-Fev (Grupo Especial)] | N32: 06:00 | O32: Sambodromo x EG | P32: 46070 | Q32: =LEFT(N32,2)&"h" -> 06h
A33: =IF(LEN(F33)>1,F33,G33)&O33&P33&Q33 -> 03139095473Sambodromo x EG4607406h | B33: =IF(LEN(F33)>1,F33,G33)&O33&P33 -> 03139095473Sambodromo x EG46074 | C33: =IF((IFERROR(IFERROR(VLOOKUP(A33,Controle_Utiliz!A:A,1,0),VLOOKUP(B33,Controle_Utiliz!B:B,1,0)),"Não Utilizou"))="Não Utilizou","Não Utilizou","Agendado") -> Agendado | D33: ALBERTO CAVALCANTI LIRA DA SILVA | E33: Prestador - Top Service | G33: 03139095473 | H33: 21967041708 | I33: FJI - CSC OGA | J33: Prestador - Top Service | K33: Prestador - Top Service | L33: Prestador - Top Service | M33: Sambódromo x EG | Vem [CAMPEÃES, Sáb, 21-Fev (Desfile das Campeãs).] | N33: 06:00 | O33: Sambodromo x EG | P33: 46074 | Q33: =LEFT(N33,2)&"h" -> 06h
A34: =IF(LEN(F34)>1,F34,G34)&O34&P34&Q34 -> 49605JB x Sambodromo4606819h | B34: =IF(LEN(F34)>1,F34,G34)&O34&P34 -> 49605JB x Sambodromo46068 | C34: =IF((IFERROR(IFERROR(VLOOKUP(A34,Controle_Utiliz!A:A,1,0),VLOOKUP(B34,Controle_Utiliz!B:B,1,0)),"Não Utilizou"))="Não Utilizou","Não Utilizou","Agendado") -> Agendado | D34: Alessandra Albuquerque | E34: Globo | F34: 49605 | H34: 21997311979 | I34: REDES PD | J34: PRODUCAO EM VIDEO | K34: NILO CESAR BARROS GUIMARAES MAIA | L34: PRODUTOR VIDEO III | M34: JB x Sambódromo | Vai [1º Dia, Dom, 15-Fev (Grupo Especial)] | N34: 19:00 | O34: JB x Sambodromo | P34: 46068 | Q34: =LEFT(N34,2)&"h" -> 19h
A35: =IF(LEN(F35)>1,F35,G35)&O35&P35&Q35 -> 49605JB x Sambodromo4606920h | B35: =IF(LEN(F35)>1,F35,G35)&O35&P35 -> 49605JB x Sambodromo46069 | C35: =IF((IFERROR(IFERROR(VLOOKUP(A35,Controle_Utiliz!A:A,1,0),VLOOKUP(B35,Controle_Utiliz!B:B,1,0)),"Não Utilizou"))="Não Utilizou","Não Utilizou","Agendado") -> Agendado | D35: Alessandra Albuquerque | E35: Globo | F35: 49605 | H35: 21997311979 | I35: REDES PD | J35: PRODUCAO EM VIDEO | K35: NILO CESAR BARROS GUIMARAES MAIA | L35: PRODUTOR VIDEO III | M35: JB x Sambódromo | Vai [2º Dia, Seg, 16-Fev (Grupo Especial)] | N35: 20:00 | O35: JB x Sambodromo | P35: 46069 | Q35: =LEFT(N35,2)&"h" -> 20h
A36: =IF(LEN(F36)>1,F36,G36)&O36&P36&Q36 -> 49605JB x Sambodromo4607020h | B36: =IF(LEN(F36)>1,F36,G36)&O36&P36 -> 49605JB x Sambodromo46070 | C36: =IF((IFERROR(IFERROR(VLOOKUP(A36,Controle_Utiliz!A:A,1,0),VLOOKUP(B36,Controle_Utiliz!B:B,1,0)),"Não Utilizou"))="Não Utilizou","Não Utilizou","Agendado") -> Agendado | D36: Alessandra Albuquerque | E36: Globo | F36: 49605 | H36: 21997311979 | I36: REDES PD | J36: PRODUCAO EM VIDEO | K36: NILO CESAR BARROS GUIMARAES MAIA | L36: PRODUTOR VIDEO III | M36: JB x Sambódromo | Vai [3º Dia, Ter, 17-Fev (Grupo Especial)] | N36: 20:00 | O36: JB x Sambodromo | P36: 46070 | Q36: =LEFT(N36,2)&"h" -> 20h
A37: =IF(LEN(F37)>1,F37,G37)&O37&P37&Q37 -> 49605JB x Sambodromo4607420h | B37: =IF(LEN(F37)>1,F37,G37)&O37&P37 -> 49605JB x Sambodromo46074 | C37: =IF((IFERROR(IFERROR(VLOOKUP(A37,Controle_Utiliz!A:A,1,0),VLOOKUP(B37,Controle_Utiliz!B:B,1,0)),"Não Utilizou"))="Não Utilizou","Não Utilizou","Agendado") -> Agendado | D37: Alessandra Albuquerque | E37: Globo | F37: 49605 | H37: 21997311979 | I37: REDES PD | J37: PRODUCAO EM VIDEO | K37: NILO CESAR BARROS GUIMARAES MAIA | L37: PRODUTOR VIDEO III | M37: JB x Sambódromo | Vai [CAMPEÃES, Sáb, 21-Fev (Desfile das Campeãs).] | N37: 20:00 | O37: JB x Sambodromo | P37: 46074 | Q37: =LEFT(N37,2)&"h" -> 20h
A38: =IF(LEN(F38)>1,F38,G38)&O38&P38&Q38 -> 49605Sambodromo x JB4606804h | B38: =IF(LEN(F38)>1,F38,G38)&O38&P38 -> 49605Sambodromo x JB46068 | C38: =IF((IFERROR(IFERROR(VLOOKUP(A38,Controle_Utiliz!A:A,1,0),VLOOKUP(B38,Controle_Utiliz!B:B,1,0)),"Não Utilizou"))="Não Utilizou","Não Utilizou","Agendado") -> Agendado | D38: Alessandra Albuquerque | E38: Globo | F38: 49605 | H38: 21997311979 | I38: REDES PD | J38: PRODUCAO EM VIDEO | K38: NILO CESAR BARROS GUIMARAES MAIA | L38: PRODUTOR VIDEO III | M38: Sambódromo x JB | Vem [1º Dia, Dom, 15-Fev (Grupo Especial)] | N38: 04:00 | O38: Sambodromo x JB | P38: 46068 | Q38: =LEFT(N38,2)&"h" -> 04h
A39: =IF(LEN(F39)>1,F39,G39)&O39&P39&Q39 -> 49605Sambodromo x JB4606904h | B39: =IF(LEN(F39)>1,F39,G39)&O39&P39 -> 49605Sambodromo x JB46069 | C39: =IF((IFERROR(IFERROR(VLOOKUP(A39,Controle_Utiliz!A:A,1,0),VLOOKUP(B39,Controle_Utiliz!B:B,1,0)),"Não Utilizou"))="Não Utilizou","Não Utilizou","Agendado") -> Agendado | D39: Alessandra Albuquerque | E39: Globo | F39: 49605 | H39: 21997311979 | I39: REDES PD | J39: PRODUCAO EM VIDEO | K39: NILO CESAR BARROS GUIMARAES MAIA | L39: PRODUTOR VIDEO III | M39: Sambódromo x JB | Vem [2º Dia, Seg, 16-Fev (Grupo Especial)] | N39: 04:00 | O39: Sambodromo x JB | P39: 46069 | Q39: =LEFT(N39,2)&"h" -> 04h
A40: =IF(LEN(F40)>1,F40,G40)&O40&P40&Q40 -> 49605Sambodromo x JB4607004h | B40: =IF(LEN(F40)>1,F40,G40)&O40&P40 -> 49605Sambodromo x JB46070 | C40: =IF((IFERROR(IFERROR(VLOOKUP(A40,Controle_Utiliz!A:A,1,0),VLOOKUP(B40,Controle_Utiliz!B:B,1,0)),"Não Utilizou"))="Não Utilizou","Não Utilizou","Agendado") -> Agendado | D40: Alessandra Albuquerque | E40: Globo | F40: 49605 | H40: 21997311979 | I40: REDES PD | J40: PRODUCAO EM VIDEO | K40: NILO CESAR BARROS GUIMARAES MAIA | L40: PRODUTOR VIDEO III | M40: Sambódromo x JB | Vem [3º Dia, Ter, 17-Fev (Grupo Especial)] | N40: 04:00 | O40: Sambodromo x JB | P40: 46070 | Q40: =LEFT(N40,2)&"h" -> 04h
A41: =IF(LEN(F41)>1,F41,G41)&O41&P41&Q41 -> 49605Sambodromo x JB4607404h | B41: =IF(LEN(F41)>1,F41,G41)&O41&P41 -> 49605Sambodromo x JB46074 | C41: =IF((IFERROR(IFERROR(VLOOKUP(A41,Controle_Utiliz!A:A,1,0),VLOOKUP(B41,Controle_Utiliz!B:B,1,0)),"Não Utilizou"))="Não Utilizou","Não Utilizou","Agendado") -> Não Utilizou | D41: Alessandra Albuquerque | E41: Globo | F41: 49605 | H41: 21997311979 | I41: REDES PD | J41: PRODUCAO EM VIDEO | K41: NILO CESAR BARROS GUIMARAES MAIA | L41: PRODUTOR VIDEO III | M41: Sambódromo x JB | Vem [CAMPEÃES, Sáb, 21-Fev (Desfile das Campeãs).] | N41: 04:00 | O41: Sambodromo x JB | P41: 46074 | Q41: =LEFT(N41,2)&"h" -> 04h
A42: =IF(LEN(F42)>1,F42,G42)&O42&P42&Q42 -> 57264EG x Sambodromo4607417h | B42: =IF(LEN(F42)>1,F42,G42)&O42&P42 -> 57264EG x Sambodromo46074 | C42: =IF((IFERROR(IFERROR(VLOOKUP(A42,Controle_Utiliz!A:A,1,0),VLOOKUP(B42,Controle_Utiliz!B:B,1,0)),"Não Utilizou"))="Não Utilizou","Não Utilizou","Agendado") -> Agendado | D42: Alex Ananias Alves | E42: Globo | F42: 57264 | H42: 21964214422 | I42: ESTRATÉGIA E TECNOLOGIA | J42: IMAGEM EG | K42: FABIO LOEWENBACH CASCAO | L42: OPER CAMERA I | M42: EG x Sambódromo | Vai [CAMPEÃES, Sáb, 21-Fev (Desfile das Campeãs).] | N42: 17:00 | O42: EG x Sambodromo | P42: 46074 | Q42: =LEFT(N42,2)&"h" -> 17h
A43: =IF(LEN(F43)>1,F43,G43)&O43&P43&Q43 -> 57264Sambodromo x EG4607403h | B43: =IF(LEN(F43)>1,F43,G43)&O43&P43 -> 57264Sambodromo x EG46074 | C43: =IF((IFERROR(IFERROR(VLOOKUP(A43,Controle_Utiliz!A:A,1,0),VLOOKUP(B43,Controle_Utiliz!B:B,1,0)),"Não Utilizou"))="Não Utilizou","Não Utilizou","Agendado") -> Não Utilizou | D43: Alex Ananias Alves | E43: Globo | F43: 57264 | H43: 21964214422 | I43: ESTRATÉGIA E TECNOLOGIA | J43: IMAGEM EG | K43: FABIO LOEWENBACH CASCAO | L43: OPER CAMERA I | M43: Sambódromo x EG | Vem [CAMPEÃES, Sáb, 21-Fev (Desfile das Campeãs).] | N43: 03:00 | O43: Sambodromo x EG | P43: 46074 | Q43: =LEFT(N43,2)&"h" -> 03h
...

Sheet Controle_Utiliz
A1: Chave Agend | B1: Chave data | C1: NOME | D1: MATRÍCULA | E1: DOCUMENTO | F1: TRECHO | G1: SAÍDA | H1: DATA | I1: DIA | J1: AGENDAMENTO | K1: N1 | L1: Departamento | M1: Gestor Imediato | N1: Cargo | R1: 46068 | S1: =R1+1 -> 46069 | T1: =S1+1 -> 46070 | U1: 46074
A2: =IF(LEN(D2)>1,D2,E2)&F2&H2&G2 -> 87678EG x Sambodromo4606823h | B2: =IF(LEN(D2)>1,D2,E2)&F2&H2 -> 87678EG x Sambodromo46068 | C2: ADILSON ANDRADE | D2: 87678 | F2: EG x Sambodromo | G2: 23h | H2: =IF(LEFT(I2,1)="1",46068,IF(LEFT(I2,1)="2",46069,IF(LEFT(I2,1)="3",46070,46074))) -> 46068 | I2: 1 - Primeiro dia | J2: =IF(LEN(A2&B2)<2,"Não Utilizou",IF((IFERROR(IFERROR(VLOOKUP(A2,Agendamento!A:C,3,0),VLOOKUP(B2,Agendamento!B:C,2,0)&"B"),"Encaixe"))="Agendado","Agend_OK",IF((IFERROR(IFERROR(VLOOKUP(A2,Agendamento!A:C,3,0),VLOOKUP(B2,Agendamento!B:C,2,0)&"B"),"Encaixe"))="AgendadoB","Agend_NOK",IF((IFERROR(IFERROR(VLOOKUP(A2,Agendamento!A:C,3,0),VLOOKUP(B2,Agendamento!B:C,2,0)&"B"),"Encaixe"))="Encaixe","Encaixe","Não Utilizou")))) -> Encaixe | K2: =IFERROR(VLOOKUP(L2,'Base Colaboradores'!C:F,4,0),"PRESTADOR DE SERVIÇOS") -> FINANCAS JURIDICO E INFRAESTRUTURA | L2: TRANSPORTES RJ | M2: FABIO PAIXAO DOS SANTOS | N2: MOTORISTA CARRETEIRO | R2: =R1 -> 46068 | S2: =S1 -> 46069 | T2: =T1 -> 46070 | U2: =U1 -> 46074
A3: =IF(LEN(D3)>1,D3,E3)&F3&H3&G3 -> 32636EG x Sambodromo4606817h | B3: =IF(LEN(D3)>1,D3,E3)&F3&H3 -> 32636EG x Sambodromo46068 | C3: ADILSON COUTINHO | D3: 32636 | F3: EG x Sambodromo | G3: 17h | H3: =IF(LEFT(I3,1)="1",46068,IF(LEFT(I3,1)="2",46069,IF(LEFT(I3,1)="3",46070,46074))) -> 46068 | I3: 1 - Primeiro dia | J3: =IF(LEN(A3&B3)<2,"Não Utilizou",IF((IFERROR(IFERROR(VLOOKUP(A3,Agendamento!A:C,3,0),VLOOKUP(B3,Agendamento!B:C,2,0)&"B"),"Encaixe"))="Agendado","Agend_OK",IF((IFERROR(IFERROR(VLOOKUP(A3,Agendamento!A:C,3,0),VLOOKUP(B3,Agendamento!B:C,2,0)&"B"),"Encaixe"))="AgendadoB","Agend_NOK",IF((IFERROR(IFERROR(VLOOKUP(A3,Agendamento!A:C,3,0),VLOOKUP(B3,Agendamento!B:C,2,0)&"B"),"Encaixe"))="Encaixe","Encaixe","Não Utilizou")))) -> Agend_NOK | K3: =IFERROR(VLOOKUP(L3,'Base Colaboradores'!C:F,4,0),"PRESTADOR DE SERVIÇOS") -> TECNOLOGIA | L3: IMAGEM JB | M3: JEAN CARLO GOULART ALVES | N3: OPER CAMERA II
A4: =IF(LEN(D4)>1,D4,E4)&F4&H4&G4 -> 03139095473EG x Sambodromo4606818h | B4: =IF(LEN(D4)>1,D4,E4)&F4&H4 -> 03139095473EG x Sambodromo46068 | C4: ALBERTO CAVALCANTI | E4: 03139095473 | F4: EG x Sambodromo | G4: 18h | H4: =IF(LEFT(I4,1)="1",46068,IF(LEFT(I4,1)="2",46069,IF(LEFT(I4,1)="3",46070,46074))) -> 46068 | I4: 1 - Primeiro dia | J4: =IF(LEN(A4&B4)<2,"Não Utilizou",IF((IFERROR(IFERROR(VLOOKUP(A4,Agendamento!A:C,3,0),VLOOKUP(B4,Agendamento!B:C,2,0)&"B"),"Encaixe"))="Agendado","Agend_OK",IF((IFERROR(IFERROR(VLOOKUP(A4,Agendamento!A:C,3,0),VLOOKUP(B4,Agendamento!B:C,2,0)&"B"),"Encaixe"))="AgendadoB","Agend_NOK",IF((IFERROR(IFERROR(VLOOKUP(A4,Agendamento!A:C,3,0),VLOOKUP(B4,Agendamento!B:C,2,0)&"B"),"Encaixe"))="Encaixe","Encaixe","Não Utilizou")))) -> Agend_OK | K4: =IFERROR(VLOOKUP(L4,'Base Colaboradores'!C:F,4,0),"PRESTADOR DE SERVIÇOS") -> PRESTADOR DE SERVIÇOS | L4: Top Service | M4: Prestador | N4: Prestador
A5: =IF(LEN(D5)>1,D5,E5)&F5&H5&G5 -> 54495EG x Sambodromo4606817h | B5: =IF(LEN(D5)>1,D5,E5)&F5&H5 -> 54495EG x Sambodromo46068 | C5: ALBERTO FERNANDES | D5: 54495 | F5: EG x Sambodromo | G5: 17h | H5: =IF(LEFT(I5,1)="1",46068,IF(LEFT(I5,1)="2",46069,IF(LEFT(I5,1)="3",46070,46074))) -> 46068 | I5: 1 - Primeiro dia | J5: =IF(LEN(A5&B5)<2,"Não Utilizou",IF((IFERROR(IFERROR(VLOOKUP(A5,Agendamento!A:C,3,0),VLOOKUP(B5,Agendamento!B:C,2,0)&"B"),"Encaixe"))="Agendado","Agend_OK",IF((IFERROR(IFERROR(VLOOKUP(A5,Agendamento!A:C,3,0),VLOOKUP(B5,Agendamento!B:C,2,0)&"B"),"Encaixe"))="AgendadoB","Agend_NOK",IF((IFERROR(IFERROR(VLOOKUP(A5,Agendamento!A:C,3,0),VLOOKUP(B5,Agendamento!B:C,2,0)&"B"),"Encaixe"))="Encaixe","Encaixe","Não Utilizou")))) -> Agend_OK | K5: =IFERROR(VLOOKUP(L5,'Base Colaboradores'!C:F,4,0),"PRESTADOR DE SERVIÇOS") -> JORNALISMO | L5: SUPERVISAO IMAGEM RJ | M5: MARCIO STERNICK | N5: SUP EXEC CINEGRAFIA
A6: =IF(LEN(D6)>1,D6,E6)&F6&H6&G6 -> 49605JB x Sambodromo4606818h | B6: =IF(LEN(D6)>1,D6,E6)&F6&H6 -> 49605JB x Sambodromo46068 | C6: ALESSANDRA ALBUQUERQUE | D6: 49605 | F6: JB x Sambodromo | G6: 18h | H6: =IF(LEFT(I6,1)="1",46068,IF(LEFT(I6,1)="2",46069,IF(LEFT(I6,1)="3",46070,46074))) -> 46068 | I6: 1 - Primeiro dia | J6: =IF(LEN(A6&B6)<2,"Não Utilizou",IF((IFERROR(IFERROR(VLOOKUP(A6,Agendamento!A:C,3,0),VLOOKUP(B6,Agendamento!B:C,2,0)&"B"),"Encaixe"))="Agendado","Agend_OK",IF((IFERROR(IFERROR(VLOOKUP(A6,Agendamento!A:C,3,0),VLOOKUP(B6,Agendamento!B:C,2,0)&"B"),"Encaixe"))="AgendadoB","Agend_NOK",IF((IFERROR(IFERROR(VLOOKUP(A6,Agendamento!A:C,3,0),VLOOKUP(B6,Agendamento!B:C,2,0)&"B"),"Encaixe"))="Encaixe","Encaixe","Não Utilizou")))) -> Agend_NOK | K6: =IFERROR(VLOOKUP(L6,'Base Colaboradores'!C:F,4,0),"PRESTADOR DE SERVIÇOS") -> PRODUTOS DIGITAIS | L6: PRODUCAO EM VIDEO | M6: NILO CESAR BARROS GUIMARAES MAIA | N6: PRODUTOR VIDEO III
A7: =IF(LEN(D7)>1,D7,E7)&F7&H7&G7 -> 28483JB x Sambodromo4606819h | B7: =IF(LEN(D7)>1,D7,E7)&F7&H7 -> 28483JB x Sambodromo46068 | C7: ALEX MONTEIRO | D7: 28483 | F7: JB x Sambodromo | G7: 19h | H7: =IF(LEFT(I7,1)="1",46068,IF(LEFT(I7,1)="2",46069,IF(LEFT(I7,1)="3",46070,46074))) -> 46068 | I7: 1 - Primeiro dia | J7: =IF(LEN(A7&B7)<2,"Não Utilizou",IF((IFERROR(IFERROR(VLOOKUP(A7,Agendamento!A:C,3,0),VLOOKUP(B7,Agendamento!B:C,2,0)&"B"),"Encaixe"))="Agendado","Agend_OK",IF((IFERROR(IFERROR(VLOOKUP(A7,Agendamento!A:C,3,0),VLOOKUP(B7,Agendamento!B:C,2,0)&"B"),"Encaixe"))="AgendadoB","Agend_NOK",IF((IFERROR(IFERROR(VLOOKUP(A7,Agendamento!A:C,3,0),VLOOKUP(B7,Agendamento!B:C,2,0)&"B"),"Encaixe"))="Encaixe","Encaixe","Não Utilizou")))) -> Agend_NOK | K7: =IFERROR(VLOOKUP(L7,'Base Colaboradores'!C:F,4,0),"PRESTADOR DE SERVIÇOS") -> TECNOLOGIA | L7: COT E EXTERNA JB | M7: BEATHRIZ VERAS DE LIMA LOPES | N7: TEC SISTEMAS AUDIOVISUAIS II
A8: =IF(LEN(D8)>1,D8,E8)&F8&H8&G8 -> 09804198835EG x Sambodromo4606817h | B8: =IF(LEN(D8)>1,D8,E8)&F8&H8 -> 09804198835EG x Sambodromo46068 | C8: ALEXANDRE DE AMEIDA | E8: 09804198835 | F8: EG x Sambodromo | G8: 17h | H8: =IF(LEFT(I8,1)="1",46068,IF(LEFT(I8,1)="2",46069,IF(LEFT(I8,1)="3",46070,46074))) -> 46068 | I8: 1 - Primeiro dia | J8: =IF(LEN(A8&B8)<2,"Não Utilizou",IF((IFERROR(IFERROR(VLOOKUP(A8,Agendamento!A:C,3,0),VLOOKUP(B8,Agendamento!B:C,2,0)&"B"),"Encaixe"))="Agendado","Agend_OK",IF((IFERROR(IFERROR(VLOOKUP(A8,Agendamento!A:C,3,0),VLOOKUP(B8,Agendamento!B:C,2,0)&"B"),"Encaixe"))="AgendadoB","Agend_NOK",IF((IFERROR(IFERROR(VLOOKUP(A8,Agendamento!A:C,3,0),VLOOKUP(B8,Agendamento!B:C,2,0)&"B"),"Encaixe"))="Encaixe","Encaixe","Não Utilizou")))) -> Encaixe | K8: =IFERROR(VLOOKUP(L8,'Base Colaboradores'!C:F,4,0),"PRESTADOR DE SERVIÇOS") -> PRESTADOR DE SERVIÇOS | L8: Prestador | M8: Prestador | N8: Prestador
A9: =IF(LEN(D9)>1,D9,E9)&F9&H9&G9 -> 81362EG x Sambodromo4606823h | B9: =IF(LEN(D9)>1,D9,E9)&F9&H9 -> 81362EG x Sambodromo46068 | C9: ALEXANDRE JOSE LIMA | D9: 81362 | F9: EG x Sambodromo | G9: 23h | H9: =IF(LEFT(I9,1)="1",46068,IF(LEFT(I9,1)="2",46069,IF(LEFT(I9,1)="3",46070,46074))) -> 46068 | I9: 1 - Primeiro dia | J9: =IF(LEN(A9&B9)<2,"Não Utilizou",IF((IFERROR(IFERROR(VLOOKUP(A9,Agendamento!A:C,3,0),VLOOKUP(B9,Agendamento!B:C,2,0)&"B"),"Encaixe"))="Agendado","Agend_OK",IF((IFERROR(IFERROR(VLOOKUP(A9,Agendamento!A:C,3,0),VLOOKUP(B9,Agendamento!B:C,2,0)&"B"),"Encaixe"))="AgendadoB","Agend_NOK",IF((IFERROR(IFERROR(VLOOKUP(A9,Agendamento!A:C,3,0),VLOOKUP(B9,Agendamento!B:C,2,0)&"B"),"Encaixe"))="Encaixe","Encaixe","Não Utilizou")))) -> Agend_NOK | K9: =IFERROR(VLOOKUP(L9,'Base Colaboradores'!C:F,4,0),"PRESTADOR DE SERVIÇOS") -> JORNALISMO | L9: SUPERVISAO IMAGEM RJ | M9: EDUARDO ALBERTO FERNANDEZ | N9: REPORTER CINEMATOGRAFICO II
A10: =IF(LEN(D10)>1,D10,E10)&F10&H10&G10 -> 91802JB x Sambodromo4606818h | B10: =IF(LEN(D10)>1,D10,E10)&F10&H10 -> 91802JB x Sambodromo46068 | C10: ANA PAULA CAVALCANTE | D10: 91802 | F10: JB x Sambodromo | G10: 18h | H10: =IF(LEFT(I10,1)="1",46068,IF(LEFT(I10,1)="2",46069,IF(LEFT(I10,1)="3",46070,46074))) -> 46068 | I10: 1 - Primeiro dia | J10: =IF(LEN(A10&B10)<2,"Não Utilizou",IF((IFERROR(IFERROR(VLOOKUP(A10,Agendamento!A:C,3,0),VLOOKUP(B10,Agendamento!B:C,2,0)&"B"),"Encaixe"))="Agendado","Agend_OK",IF((IFERROR(IFERROR(VLOOKUP(A10,Agendamento!A:C,3,0),VLOOKUP(B10,Agendamento!B:C,2,0)&"B"),"Encaixe"))="AgendadoB","Agend_NOK",IF((IFERROR(IFERROR(VLOOKUP(A10,Agendamento!A:C,3,0),VLOOKUP(B10,Agendamento!B:C,2,0)&"B"),"Encaixe"))="Encaixe","Encaixe","Não Utilizou")))) -> Encaixe | K10: =IFERROR(VLOOKUP(L10,'Base Colaboradores'!C:F,4,0),"PRESTADOR DE SERVIÇOS") -> TECNOLOGIA | L10: COT E EXTERNA JB | M10: BEATHRIZ VERAS DE LIMA LOPES | N10: TEC CAPTACAO SOM I
A11: =IF(LEN(D11)>1,D11,E11)&F11&H11&G11 -> 41204EG x Sambodromo4606817h | B11: =IF(LEN(D11)>1,D11,E11)&F11&H11 -> 41204EG x Sambodromo46068 | C11: ANDERSON GUIMARAES | D11: 41204 | F11: EG x Sambodromo | G11: 17h | H11: =IF(LEFT(I11,1)="1",46068,IF(LEFT(I11,1)="2",46069,IF(LEFT(I11,1)="3",46070,46074))) -> 46068 | I11: 1 - Primeiro dia | J11: =IF(LEN(A11&B11)<2,"Não Utilizou",IF((IFERROR(IFERROR(VLOOKUP(A11,Agendamento!A:C,3,0),VLOOKUP(B11,Agendamento!B:C,2,0)&"B"),"Encaixe"))="Agendado","Agend_OK",IF((IFERROR(IFERROR(VLOOKUP(A11,Agendamento!A:C,3,0),VLOOKUP(B11,Agendamento!B:C,2,0)&"B"),"Encaixe"))="AgendadoB","Agend_NOK",IF((IFERROR(IFERROR(VLOOKUP(A11,Agendamento!A:C,3,0),VLOOKUP(B11,Agendamento!B:C,2,0)&"B"),"Encaixe"))="Encaixe","Encaixe","Não Utilizou")))) -> Agend_OK | K11: =IFERROR(VLOOKUP(L11,'Base Colaboradores'!C:F,4,0),"PRESTADOR DE SERVIÇOS") -> TECNOLOGIA | L11: IMAGEM EG | M11: FABIO LOEWENBACH CASCAO | N11: OPER CAMERA IV
A12: =IF(LEN(D12)>1,D12,E12)&F12&H12&G12 -> 39276JB x Sambodromo4606821h | B12: =IF(LEN(D12)>1,D12,E12)&F12&H12 -> 39276JB x Sambodromo46068 | C12: ANDRE CARVALHO | D12: 39276 | F12: JB x Sambodromo | G12: 21h | H12: =IF(LEFT(I12,1)="1",46068,IF(LEFT(I12,1)="2",46069,IF(LEFT(I12,1)="3",46070,46074))) -> 46068 | I12: 1 - Primeiro dia | J12: =IF(LEN(A12&B12)<2,"Não Utilizou",IF((IFERROR(IFERROR(VLOOKUP(A12,Agendamento!A:C,3,0),VLOOKUP(B12,Agendamento!B:C,2,0)&"B"),"Encaixe"))="Agendado","Agend_OK",IF((IFERROR(IFERROR(VLOOKUP(A12,Agendamento!A:C,3,0),VLOOKUP(B12,Agendamento!B:C,2,0)&"B"),"Encaixe"))="AgendadoB","Agend_NOK",IF((IFERROR(IFERROR(VLOOKUP(A12,Agendamento!A:C,3,0),VLOOKUP(B12,Agendamento!B:C,2,0)&"B"),"Encaixe"))="Encaixe","Encaixe","Não Utilizou")))) -> Encaixe | K12: =IFERROR(VLOOKUP(L12,'Base Colaboradores'!C:F,4,0),"PRESTADOR DE SERVIÇOS") -> TV GLOBO | L12: SUPERVISAO PROGRAMACAO RIO DE JANEIRO | M12: ALINE SILVA SANTOS | N12: COORD PROGRAMACAO REGIONAL
A13: =IF(LEN(D13)>1,D13,E13)&F13&H13&G13 -> 01193644763EG x Sambodromo4606822h | B13: =IF(LEN(D13)>1,D13,E13)&F13&H13 -> 01193644763EG x Sambodromo46068 | C13: ANDREIA CARLA | E13: 01193644763 | F13: EG x Sambodromo | G13: 22h | H13: =IF(LEFT(I13,1)="1",46068,IF(LEFT(I13,1)="2",46069,IF(LEFT(I13,1)="3",46070,46074))) -> 46068 | I13: 1 - Primeiro dia | J13: =IF(LEN(A13&B13)<2,"Não Utilizou",IF((IFERROR(IFERROR(VLOOKUP(A13,Agendamento!A:C,3,0),VLOOKUP(B13,Agendamento!B:C,2,0)&"B"),"Encaixe"))="Agendado","Agend_OK",IF((IFERROR(IFERROR(VLOOKUP(A13,Agendamento!A:C,3,0),VLOOKUP(B13,Agendamento!B:C,2,0)&"B"),"Encaixe"))="AgendadoB","Agend_NOK",IF((IFERROR(IFERROR(VLOOKUP(A13,Agendamento!A:C,3,0),VLOOKUP(B13,Agendamento!B:C,2,0)&"B"),"Encaixe"))="Encaixe","Encaixe","Não Utilizou")))) -> Encaixe | K13: =IFERROR(VLOOKUP(L13,'Base Colaboradores'!C:F,4,0),"PRESTADOR DE SERVIÇOS") -> PRESTADOR DE SERVIÇOS | L13: Prestador | M13: Prestador | N13: Prestador
A14: =IF(LEN(D14)>1,D14,E14)&F14&H14&G14 -> 05551438724JB x Sambodromo4606819h | B14: =IF(LEN(D14)>1,D14,E14)&F14&H14 -> 05551438724JB x Sambodromo46068 | C14: ANTONIO PIMENTEL | E14: 05551438724 | F14: JB x Sambodromo | G14: 19h | H14: =IF(LEFT(I14,1)="1",46068,IF(LEFT(I14,1)="2",46069,IF(LEFT(I14,1)="3",46070,46074))) -> 46068 | I14: 1 - Primeiro dia | J14: =IF(LEN(A14&B14)<2,"Não Utilizou",IF((IFERROR(IFERROR(VLOOKUP(A14,Agendamento!A:C,3,0),VLOOKUP(B14,Agendamento!B:C,2,0)&"B"),"Encaixe"))="Agendado","Agend_OK",IF((IFERROR(IFERROR(VLOOKUP(A14,Agendamento!A:C,3,0),VLOOKUP(B14,Agendamento!B:C,2,0)&"B"),"Encaixe"))="AgendadoB","Agend_NOK",IF((IFERROR(IFERROR(VLOOKUP(A14,Agendamento!A:C,3,0),VLOOKUP(B14,Agendamento!B:C,2,0)&"B"),"Encaixe"))="Encaixe","Encaixe","Não Utilizou")))) -> Encaixe | K14: =IFERROR(VLOOKUP(L14,'Base Colaboradores'!C:F,4,0),"PRESTADOR DE SERVIÇOS") -> PRESTADOR DE SERVIÇOS | L14: Prestador | M14: Prestador | N14: Prestador
A15: =IF(LEN(D15)>1,D15,E15)&F15&H15&G15 -> 52812EG x Sambodromo4606818h | B15: =IF(LEN(D15)>1,D15,E15)&F15&H15 -> 52812EG x Sambodromo46068 | C15: ARLAN PEREIRA | D15: 52812 | F15: EG x Sambodromo | G15: 18h | H15: =IF(LEFT(I15,1)="1",46068,IF(LEFT(I15,1)="2",46069,IF(LEFT(I15,1)="3",46070,46074))) -> 46068 | I15: 1 - Primeiro dia | J15: =IF(LEN(A15&B15)<2,"Não Utilizou",IF((IFERROR(IFERROR(VLOOKUP(A15,Agendamento!A:C,3,0),VLOOKUP(B15,Agendamento!B:C,2,0)&"B"),"Encaixe"))="Agendado","Agend_OK",IF((IFERROR(IFERROR(VLOOKUP(A15,Agendamento!A:C,3,0),VLOOKUP(B15,Agendamento!B:C,2,0)&"B"),"Encaixe"))="AgendadoB","Agend_NOK",IF((IFERROR(IFERROR(VLOOKUP(A15,Agendamento!A:C,3,0),VLOOKUP(B15,Agendamento!B:C,2,0)&"B"),"Encaixe"))="Encaixe","Encaixe","Não Utilizou")))) -> Agend_NOK | K15: =IFERROR(VLOOKUP(L15,'Base Colaboradores'!C:F,4,0),"PRESTADOR DE SERVIÇOS") -> FINANCAS JURIDICO E INFRAESTRUTURA | L15: DRAMATURGIA DIARIA | M15: THIAGO GOMES BRANDAO | N15: MONTADOR III
A16: =IF(LEN(D16)>1,D16,E16)&F16&H16&G16 -> 70088JB x Sambodromo4606818h | B16: =IF(LEN(D16)>1,D16,E16)&F16&H16 -> 70088JB x Sambodromo46068 | C16: BETTE LUCCHESE | D16: 70088 | F16: JB x Sambodromo | G16: 18h | H16: =IF(LEFT(I16,1)="1",46068,IF(LEFT(I16,1)="2",46069,IF(LEFT(I16,1)="3",46070,46074))) -> 46068 | I16: 1 - Primeiro dia | J16: =IF(LEN(A16&B16)<2,"Não Utilizou",IF((IFERROR(IFERROR(VLOOKUP(A16,Agendamento!A:C,3,0),VLOOKUP(B16,Agendamento!B:C,2,0)&"B"),"Encaixe"))="Agendado","Agend_OK",IF((IFERROR(IFERROR(VLOOKUP(A16,Agendamento!A:C,3,0),VLOOKUP(B16,Agendamento!B:C,2,0)&"B"),"Encaixe"))="AgendadoB","Agend_NOK",IF((IFERROR(IFERROR(VLOOKUP(A16,Agendamento!A:C,3,0),VLOOKUP(B16,Agendamento!B:C,2,0)&"B"),"Encaixe"))="Encaixe","Encaixe","Não Utilizou")))) -> Agend_NOK | K16: =IFERROR(VLOOKUP(L16,'Base Colaboradores'!C:F,4,0),"PRESTADOR DE SERVIÇOS") -> JORNALISMO | L16: EDITORIA RJ | M16: MARCIO STERNICK | N16: REPORTER ESPECIAL II
A17: =IF(LEN(D17)>1,D17,E17)&F17&H17&G17 -> 84786JB x Sambodromo4606819h | B17: =IF(LEN(D17)>1,D17,E17)&F17&H17 -> 84786JB x Sambodromo46068 | C17: BIANCA FASSANO | D17: 84786 | F17: JB x Sambodromo | G17: 19h | H17: =IF(LEFT(I17,1)="1",46068,IF(LEFT(I17,1)="2",46069,IF(LEFT(I17,1)="3",46070,46074))) -> 46068 | I17: 1 - Primeiro dia | J17: =IF(LEN(A17&B17)<2,"Não Utilizou",IF((IFERROR(IFERROR(VLOOKUP(A17,Agendamento!A:C,3,0),VLOOKUP(B17,Agendamento!B:C,2,0)&"B"),"Encaixe"))="Agendado","Agend_OK",IF((IFERROR(IFERROR(VLOOKUP(A17,Agendamento!A:C,3,0),VLOOKUP(B17,Agendamento!B:C,2,0)&"B"),"Encaixe"))="AgendadoB","Agend_NOK",IF((IFERROR(IFERROR(VLOOKUP(A17,Agendamento!A:C,3,0),VLOOKUP(B17,Agendamento!B:C,2,0)&"B"),"Encaixe"))="Encaixe","Encaixe","Não Utilizou")))) -> Agend_OK | K17: =IFERROR(VLOOKUP(L17,'Base Colaboradores'!C:F,4,0),"PRESTADOR DE SERVIÇOS") -> RECURSOS HUMANOS | L17: APOIO A PESSOAS E BEM-ESTAR | M17: RENATA RODRIGUES MARTINS | N17: ANL SERVICOS RECURSOS HUMANOS II
A18: =IF(LEN(D18)>1,D18,E18)&F18&H18&G18 -> 78882EG x Sambodromo4606822h | B18: =IF(LEN(D18)>1,D18,E18)&F18&H18 -> 78882EG x Sambodromo46068 | C18: BRENDA PORTO | D18: 78882 | F18: EG x Sambodromo | G18: 22h | H18: =IF(LEFT(I18,1)="1",46068,IF(LEFT(I18,1)="2",46069,IF(LEFT(I18,1)="3",46070,46074))) -> 46068 | I18: 1 - Primeiro dia | J18: =IF(LEN(A18&B18)<2,"Não Utilizou",IF((IFERROR(IFERROR(VLOOKUP(A18,Agendamento!A:C,3,0),VLOOKUP(B18,Agendamento!B:C,2,0)&"B"),"Encaixe"))="Agendado","Agend_OK",IF((IFERROR(IFERROR(VLOOKUP(A18,Agendamento!A:C,3,0),VLOOKUP(B18,Agendamento!B:C,2,0)&"B"),"Encaixe"))="AgendadoB","Agend_NOK",IF((IFERROR(IFERROR(VLOOKUP(A18,Agendamento!A:C,3,0),VLOOKUP(B18,Agendamento!B:C,2,0)&"B"),"Encaixe"))="Encaixe","Encaixe","Não Utilizou")))) -> Agend_OK | K18: =IFERROR(VLOOKUP(L18,'Base Colaboradores'!C:F,4,0),"PRESTADOR DE SERVIÇOS") -> TECNOLOGIA | L18: IMAGEM EG | M18: FABIO LOEWENBACH CASCAO | N18: OPER CAMERA I
A19: =IF(LEN(D19)>1,D19,E19)&F19&H19&G19 -> 78728EG x Sambodromo4606822h | B19: =IF(LEN(D19)>1,D19,E19)&F19&H19 -> 78728EG x Sambodromo46068 | C19: BRUNO GONÇALVES | D19: 78728 | F19: EG x Sambodromo | G19: 22h | H19: =IF(LEFT(I19,1)="1",46068,IF(LEFT(I19,1)="2",46069,IF(LEFT(I19,1)="3",46070,46074))) -> 46068 | I19: 1 - Primeiro dia | J19: =IF(LEN(A19&B19)<2,"Não Utilizou",IF((IFERROR(IFERROR(VLOOKUP(A19,Agendamento!A:C,3,0),VLOOKUP(B19,Agendamento!B:C,2,0)&"B"),"Encaixe"))="Agendado","Agend_OK",IF((IFERROR(IFERROR(VLOOKUP(A19,Agendamento!A:C,3,0),VLOOKUP(B19,Agendamento!B:C,2,0)&"B"),"Encaixe"))="AgendadoB","Agend_NOK",IF((IFERROR(IFERROR(VLOOKUP(A19,Agendamento!A:C,3,0),VLOOKUP(B19,Agendamento!B:C,2,0)&"B"),"Encaixe"))="Encaixe","Encaixe","Não Utilizou")))) -> Agend_NOK | K19: =IFERROR(VLOOKUP(L19,'Base Colaboradores'!C:F,4,0),"PRESTADOR DE SERVIÇOS") -> TECNOLOGIA | L19: IMAGEM EG | M19: FABIO LOEWENBACH CASCAO | N19: OPER CAMERA I
A20: =IF(LEN(D20)>1,D20,E20)&F20&H20&G20 -> 905JB x Sambodromo4606819h | B20: =IF(LEN(D20)>1,D20,E20)&F20&H20 -> 905JB x Sambodromo46068 | C20: BRUNO GRUBERTT | D20: 905 | F20: JB x Sambodromo | G20: 19h | H20: =IF(LEFT(I20,1)="1",46068,IF(LEFT(I20,1)="2",46069,IF(LEFT(I20,1)="3",46070,46074))) -> 46068 | I20: 1 - Primeiro dia | J20: =IF(LEN(A20&B20)<2,"Não Utilizou",IF((IFERROR(IFERROR(VLOOKUP(A20,Agendamento!A:C,3,0),VLOOKUP(B20,Agendamento!B:C,2,0)&"B"),"Encaixe"))="Agendado","Agend_OK",IF((IFERROR(IFERROR(VLOOKUP(A20,Agendamento!A:C,3,0),VLOOKUP(B20,Agendamento!B:C,2,0)&"B"),"Encaixe"))="AgendadoB","Agend_NOK",IF((IFERROR(IFERROR(VLOOKUP(A20,Agendamento!A:C,3,0),VLOOKUP(B20,Agendamento!B:C,2,0)&"B"),"Encaixe"))="Encaixe","Encaixe","Não Utilizou")))) -> Encaixe | K20: =IFERROR(VLOOKUP(L20,'Base Colaboradores'!C:F,4,0),"PRESTADOR DE SERVIÇOS") -> JORNALISMO | L20: SUPERVISAO EDITORIA RJ | M20: PATRICIA DE ANDRADE PINTO | N20: REPORTER III
A21: =IF(LEN(D21)>1,D21,E21)&F21&H21&G21 -> 55129JB x Sambodromo4606818h | B21: =IF(LEN(D21)>1,D21,E21)&F21&H21 -> 55129JB x Sambodromo46068 | C21: BRUNO REGO | D21: 55129 | F21: JB x Sambodromo | G21: 18h | H21: =IF(LEFT(I21,1)="1",46068,IF(LEFT(I21,1)="2",46069,IF(LEFT(I21,1)="3",46070,46074))) -> 46068 | I21: 1 - Primeiro dia | J21: =IF(LEN(A21&B21)<2,"Não Utilizou",IF((IFERROR(IFERROR(VLOOKUP(A21,Agendamento!A:C,3,0),VLOOKUP(B21,Agendamento!B:C,2,0)&"B"),"Encaixe"))="Agendado","Agend_OK",IF((IFERROR(IFERROR(VLOOKUP(A21,Agendamento!A:C,3,0),VLOOKUP(B21,Agendamento!B:C,2,0)&"B"),"Encaixe"))="AgendadoB","Agend_NOK",IF((IFERROR(IFERROR(VLOOKUP(A21,Agendamento!A:C,3,0),VLOOKUP(B21,Agendamento!B:C,2,0)&"B"),"Encaixe"))="Encaixe","Encaixe","Não Utilizou")))) -> Agend_OK | K21: =IFERROR(VLOOKUP(L21,'Base Colaboradores'!C:F,4,0),"PRESTADOR DE SERVIÇOS") -> FINANCAS JURIDICO E INFRAESTRUTURA | L21: EXTERNA INTERNA JB BT | M21: RODRIGO AZEVEDO DE ARAUJO | N21: LIDER SEGURANCA
A22: =IF(LEN(D22)>1,D22,E22)&F22&H22&G22 -> 55278EG x Sambodromo4606818h | B22: =IF(LEN(D22)>1,D22,E22)&F22&H22 -> 55278EG x Sambodromo46068 | C22: BRUNO RIBEIRO | D22: 55278 | F22: EG x Sambodromo | G22: 18h | H22: =IF(LEFT(I22,1)="1",46068,IF(LEFT(I22,1)="2",46069,IF(LEFT(I22,1)="3",46070,46074))) -> 46068 | I22: 1 - Primeiro dia | J22: =IF(LEN(A22&B22)<2,"Não Utilizou",IF((IFERROR(IFERROR(VLOOKUP(A22,Agendamento!A:C,3,0),VLOOKUP(B22,Agendamento!B:C,2,0)&"B"),"Encaixe"))="Agendado","Agend_OK",IF((IFERROR(IFERROR(VLOOKUP(A22,Agendamento!A:C,3,0),VLOOKUP(B22,Agendamento!B:C,2,0)&"B"),"Encaixe"))="AgendadoB","Agend_NOK",IF((IFERROR(IFERROR(VLOOKUP(A22,Agendamento!A:C,3,0),VLOOKUP(B22,Agendamento!B:C,2,0)&"B"),"Encaixe"))="Encaixe","Encaixe","Não Utilizou")))) -> Agend_OK | K22: =IFERROR(VLOOKUP(L22,'Base Colaboradores'!C:F,4,0),"PRESTADOR DE SERVIÇOS") -> FINANCAS JURIDICO E INFRAESTRUTURA | L22: CONSERVACAO PREDIAL EG | M22: THIAGO LACERDA DE LA VEGA | N22: COORD MANUTENCAO E OPERACAO PREDIAL
A23: =IF(LEN(D23)>1,D23,E23)&F23&H23&G23 -> 15692202719EG x Sambodromo4606819h | B23: =IF(LEN(D23)>1,D23,E23)&F23&H23 -> 15692202719EG x Sambodromo46068 | C23: CARINA RITTER | E23: 15692202719 | F23: EG x Sambodromo | G23: 19h | H23: =IF(LEFT(I23,1)="1",46068,IF(LEFT(I23,1)="2",46069,IF(LEFT(I23,1)="3",46070,46074))) -> 46068 | I23: 1 - Primeiro dia | J23: =IF(LEN(A23&B23)<2,"Não Utilizou",IF((IFERROR(IFERROR(VLOOKUP(A23,Agendamento!A:C,3,0),VLOOKUP(B23,Agendamento!B:C,2,0)&"B"),"Encaixe"))="Agendado","Agend_OK",IF((IFERROR(IFERROR(VLOOKUP(A23,Agendamento!A:C,3,0),VLOOKUP(B23,Agendamento!B:C,2,0)&"B"),"Encaixe"))="AgendadoB","Agend_NOK",IF((IFERROR(IFERROR(VLOOKUP(A23,Agendamento!A:C,3,0),VLOOKUP(B23,Agendamento!B:C,2,0)&"B"),"Encaixe"))="Encaixe","Encaixe","Não Utilizou")))) -> Agend_NOK | K23: =IFERROR(VLOOKUP(L23,'Base Colaboradores'!C:F,4,0),"PRESTADOR DE SERVIÇOS") -> PRESTADOR DE SERVIÇOS | L23: LET | M23: Prestador | N23: Prestador
A24: =IF(LEN(D24)>1,D24,E24)&F24&H24&G24 -> 08784901756EG x Sambodromo4606820h | B24: =IF(LEN(D24)>1,D24,E24)&F24&H24 -> 08784901756EG x Sambodromo46068 | C24: CARLOS ALBERTO | E24: 08784901756 | F24: EG x Sambodromo | G24: 20h | H24: =IF(LEFT(I24,1)="1",46068,IF(LEFT(I24,1)="2",46069,IF(LEFT(I24,1)="3",46070,46074))) -> 46068 | I24: 1 - Primeiro dia | J24: =IF(LEN(A24&B24)<2,"Não Utilizou",IF((IFERROR(IFERROR(VLOOKUP(A24,Agendamento!A:C,3,0),VLOOKUP(B24,Agendamento!B:C,2,0)&"B"),"Encaixe"))="Agendado","Agend_OK",IF((IFERROR(IFERROR(VLOOKUP(A24,Agendamento!A:C,3,0),VLOOKUP(B24,Agendamento!B:C,2,0)&"B"),"Encaixe"))="AgendadoB","Agend_NOK",IF((IFERROR(IFERROR(VLOOKUP(A24,Agendamento!A:C,3,0),VLOOKUP(B24,Agendamento!B:C,2,0)&"B"),"Encaixe"))="Encaixe","Encaixe","Não Utilizou")))) -> Agend_NOK | K24: =IFERROR(VLOOKUP(L24,'Base Colaboradores'!C:F,4,0),"PRESTADOR DE SERVIÇOS") -> PRESTADOR DE SERVIÇOS | L24: Top Service | M24: Prestador | N24: Prestador
A25: =IF(LEN(D25)>1,D25,E25)&F25&H25&G25 -> 54103JB x Sambodromo4606818h | B25: =IF(LEN(D25)>1,D25,E25)&F25&H25 -> 54103JB x Sambodromo46068 | C25: CARLOS MENDONÇA | D25: 54103 | F25: JB x Sambodromo | G25: 18h | H25: =IF(LEFT(I25,1)="1",46068,IF(LEFT(I25,1)="2",46069,IF(LEFT(I25,1)="3",46070,46074))) -> 46068 | I25: 1 - Primeiro dia | J25: =IF(LEN(A25&B25)<2,"Não Utilizou",IF((IFERROR(IFERROR(VLOOKUP(A25,Agendamento!A:C,3,0),VLOOKUP(B25,Agendamento!B:C,2,0)&"B"),"Encaixe"))="Agendado","Agend_OK",IF((IFERROR(IFERROR(VLOOKUP(A25,Agendamento!A:C,3,0),VLOOKUP(B25,Agendamento!B:C,2,0)&"B"),"Encaixe"))="AgendadoB","Agend_NOK",IF((IFERROR(IFERROR(VLOOKUP(A25,Agendamento!A:C,3,0),VLOOKUP(B25,Agendamento!B:C,2,0)&"B"),"Encaixe"))="Encaixe","Encaixe","Não Utilizou")))) -> Encaixe | K25: =IFERROR(VLOOKUP(L25,'Base Colaboradores'!C:F,4,0),"PRESTADOR DE SERVIÇOS") -> JORNALISMO | L25: SUPERVISAO IMAGEM RJ | M25: EDUARDO ALBERTO FERNANDEZ | N25: REPORTER CINEMATOGRAFICO II
A26: =IF(LEN(D26)>1,D26,E26)&F26&H26&G26 -> 89545EG x Sambodromo4606819h | B26: =IF(LEN(D26)>1,D26,E26)&F26&H26 -> 89545EG x Sambodromo46068 | C26: CARLOS PAIVA | D26: 89545 | F26: EG x Sambodromo | G26: 19h | H26: =IF(LEFT(I26,1)="1",46068,IF(LEFT(I26,1)="2",46069,IF(LEFT(I26,1)="3",46070,46074))) -> 46068 | I26: 1 - Primeiro dia | J26: =IF(LEN(A26&B26)<2,"Não Utilizou",IF((IFERROR(IFERROR(VLOOKUP(A26,Agendamento!A:C,3,0),VLOOKUP(B26,Agendamento!B:C,2,0)&"B"),"Encaixe"))="Agendado","Agend_OK",IF((IFERROR(IFERROR(VLOOKUP(A26,Agendamento!A:C,3,0),VLOOKUP(B26,Agendamento!B:C,2,0)&"B"),"Encaixe"))="AgendadoB","Agend_NOK",IF((IFERROR(IFERROR(VLOOKUP(A26,Agendamento!A:C,3,0),VLOOKUP(B26,Agendamento!B:C,2,0)&"B"),"Encaixe"))="Encaixe","Encaixe","Não Utilizou")))) -> Agend_NOK | K26: =IFERROR(VLOOKUP(L26,'Base Colaboradores'!C:F,4,0),"PRESTADOR DE SERVIÇOS") -> PRODUTOS DIGITAIS | L26: CULTURA POP 2 | M26: ANDERSON DEZAN RIBEIRO DE AZEVEDO | N26: EDITOR CONTEUDO WEB I
A27: =IF(LEN(D27)>1,D27,E27)&F27&H27&G27 -> 984JB x Sambodromo4606819h | B27: =IF(LEN(D27)>1,D27,E27)&F27&H27 -> 984JB x Sambodromo46068 | C27: CAROLINA DUCA | D27: 984 | F27: JB x Sambodromo | G27: 19h | H27: =IF(LEFT(I27,1)="1",46068,IF(LEFT(I27,1)="2",46069,IF(LEFT(I27,1)="3",46070,46074))) -> 46068 | I27: 1 - Primeiro dia | J27: =IF(LEN(A27&B27)<2,"Não Utilizou",IF((IFERROR(IFERROR(VLOOKUP(A27,Agendamento!A:C,3,0),VLOOKUP(B27,Agendamento!B:C,2,0)&"B"),"Encaixe"))="Agendado","Agend_OK",IF((IFERROR(IFERROR(VLOOKUP(A27,Agendamento!A:C,3,0),VLOOKUP(B27,Agendamento!B:C,2,0)&"B"),"Encaixe"))="AgendadoB","Agend_NOK",IF((IFERROR(IFERROR(VLOOKUP(A27,Agendamento!A:C,3,0),VLOOKUP(B27,Agendamento!B:C,2,0)&"B"),"Encaixe"))="Encaixe","Encaixe","Não Utilizou")))) -> Encaixe | K27: =IFERROR(VLOOKUP(L27,'Base Colaboradores'!C:F,4,0),"PRESTADOR DE SERVIÇOS") -> TECNOLOGIA | L27: INFRA E TELECOM | M27: RAYMUNDO COSTA PINTO BARROS | N27: DIR INFRA & TELECOM
A28: =IF(LEN(D28)>1,D28,E28)&F28&H28&G28 -> 41420JB x Sambodromo4606818h | B28: =IF(LEN(D28)>1,D28,E28)&F28&H28 -> 41420JB x Sambodromo46068 | C28: CHICO REGUEIRA | D28: 41420 | F28: JB x Sambodromo | G28: 18h | H28: =IF(LEFT(I28,1)="1",46068,IF(LEFT(I28,1)="2",46069,IF(LEFT(I28,1)="3",46070,46074))) -> 46068 | I28: 1 - Primeiro dia | J28: =IF(LEN(A28&B28)<2,"Não Utilizou",IF((IFERROR(IFERROR(VLOOKUP(A28,Agendamento!A:C,3,0),VLOOKUP(B28,Agendamento!B:C,2,0)&"B"),"Encaixe"))="Agendado","Agend_OK",IF((IFERROR(IFERROR(VLOOKUP(A28,Agendamento!A:C,3,0),VLOOKUP(B28,Agendamento!B:C,2,0)&"B"),"Encaixe"))="AgendadoB","Agend_NOK",IF((IFERROR(IFERROR(VLOOKUP(A28,Agendamento!A:C,3,0),VLOOKUP(B28,Agendamento!B:C,2,0)&"B"),"Encaixe"))="Encaixe","Encaixe","Não Utilizou")))) -> Encaixe | K28: =IFERROR(VLOOKUP(L28,'Base Colaboradores'!C:F,4,0),"PRESTADOR DE SERVIÇOS") -> JORNALISMO | L28: SUPERVISAO EDITORIA RJ | M28: PATRICIA DE ANDRADE PINTO | N28: REPORTER ESPECIAL I
A29: =IF(LEN(D29)>1,D29,E29)&F29&H29&G29 -> 05559496723EG x Sambodromo4606818h | B29: =IF(LEN(D29)>1,D29,E29)&F29&H29 -> 05559496723EG x Sambodromo46068 | C29: CINTHIA REGINA | E29: 05559496723 | F29: EG x Sambodromo | G29: 18h | H29: =IF(LEFT(I29,1)="1",46068,IF(LEFT(I29,1)="2",46069,IF(LEFT(I29,1)="3",46070,46074))) -> 46068 | I29: 1 - Primeiro dia | J29: =IF(LEN(A29&B29)<2,"Não Utilizou",IF((IFERROR(IFERROR(VLOOKUP(A29,Agendamento!A:C,3,0),VLOOKUP(B29,Agendamento!B:C,2,0)&"B"),"Encaixe"))="Agendado","Agend_OK",IF((IFERROR(IFERROR(VLOOKUP(A29,Agendamento!A:C,3,0),VLOOKUP(B29,Agendamento!B:C,2,0)&"B"),"Encaixe"))="AgendadoB","Agend_NOK",IF((IFERROR(IFERROR(VLOOKUP(A29,Agendamento!A:C,3,0),VLOOKUP(B29,Agendamento!B:C,2,0)&"B"),"Encaixe"))="Encaixe","Encaixe","Não Utilizou")))) -> Agend_OK | K29: =IFERROR(VLOOKUP(L29,'Base Colaboradores'!C:F,4,0),"PRESTADOR DE SERVIÇOS") -> PRESTADOR DE SERVIÇOS | L29: Top Service | M29: Prestador | N29: Prestador
A30: =IF(LEN(D30)>1,D30,E30)&F30&H30&G30 -> 02495836747EG x Sambodromo4606818h | B30: =IF(LEN(D30)>1,D30,E30)&F30&H30 -> 02495836747EG x Sambodromo46068 | C30: CLEBER CANDIDO | E30: 02495836747 | F30: EG x Sambodromo | G30: 18h | H30: =IF(LEFT(I30,1)="1",46068,IF(LEFT(I30,1)="2",46069,IF(LEFT(I30,1)="3",46070,46074))) -> 46068 | I30: 1 - Primeiro dia | J30: =IF(LEN(A30&B30)<2,"Não Utilizou",IF((IFERROR(IFERROR(VLOOKUP(A30,Agendamento!A:C,3,0),VLOOKUP(B30,Agendamento!B:C,2,0)&"B"),"Encaixe"))="Agendado","Agend_OK",IF((IFERROR(IFERROR(VLOOKUP(A30,Agendamento!A:C,3,0),VLOOKUP(B30,Agendamento!B:C,2,0)&"B"),"Encaixe"))="AgendadoB","Agend_NOK",IF((IFERROR(IFERROR(VLOOKUP(A30,Agendamento!A:C,3,0),VLOOKUP(B30,Agendamento!B:C,2,0)&"B"),"Encaixe"))="Encaixe","Encaixe","Não Utilizou")))) -> Agend_OK | K30: =IFERROR(VLOOKUP(L30,'Base Colaboradores'!C:F,4,0),"PRESTADOR DE SERVIÇOS") -> PRESTADOR DE SERVIÇOS | L30: Top Service | M30: Prestador | N30: Prestador
A31: =IF(LEN(D31)>1,D31,E31)&F31&H31&G31 -> 92563EG x Sambodromo4606820h | B31: =IF(LEN(D31)>1,D31,E31)&F31&H31 -> 92563EG x Sambodromo46068 | C31: CLEYTON COSTA | D31: 92563 | F31: EG x Sambodromo | G31: 20h | H31: =IF(LEFT(I31,1)="1",46068,IF(LEFT(I31,1)="2",46069,IF(LEFT(I31,1)="3",46070,46074))) -> 46068 | I31: 1 - Primeiro dia | J31: =IF(LEN(A31&B31)<2,"Não Utilizou",IF((IFERROR(IFERROR(VLOOKUP(A31,Agendamento!A:C,3,0),VLOOKUP(B31,Agendamento!B:C,2,0)&"B"),"Encaixe"))="Agendado","Agend_OK",IF((IFERROR(IFERROR(VLOOKUP(A31,Agendamento!A:C,3,0),VLOOKUP(B31,Agendamento!B:C,2,0)&"B"),"Encaixe"))="AgendadoB","Agend_NOK",IF((IFERROR(IFERROR(VLOOKUP(A31,Agendamento!A:C,3,0),VLOOKUP(B31,Agendamento!B:C,2,0)&"B"),"Encaixe"))="Encaixe","Encaixe","Não Utilizou")))) -> Encaixe | K31: =IFERROR(VLOOKUP(L31,'Base Colaboradores'!C:F,4,0),"PRESTADOR DE SERVIÇOS") -> FINANCAS JURIDICO E INFRAESTRUTURA | L31: TRANSPORTES RJ | M31: FABIO PAIXAO DOS SANTOS | N31: ENC SERVICOS
